Workbook

Sheet Léeme
A1: Modelo financiero — Clima Baires Argentina
A3: Versión 1.2 · acompaña al «Plan de Acción 30 Días» · TC de referencia 1.760 ARS/EUR (euro billete vendedor. Banco de la Nación Argentina. 31-07-2026)
A5: Cómo se usa
A6: Solo se edita la hoja «Supuestos»: las celdas en amarillo. Todo lo demás son fórmulas que recalculan solas.
A7: El resto de las hojas no se toca — si se pisa una fórmula con un número, el modelo deja de ser un modelo.
A9: Convención monetaria
A10: ARS constantes de agosto-2026. En Argentina los precios de venta y de compra se indexan juntos, de modo que el margen porcentual se sostiene; trabajar en nominales solo añadiría ruido inflacionario. Conversión a EUR al TC de portada.
A11: En Argentina los precios de compra y de venta se indexan casi en paralelo, así que el margen porcentual se
A12: sostiene y los valores nominales solo agregarían ruido. La conversión a euros es informativa para los socios.
A14: Qué NO hay que creerse
A15: La curva de obras/mes es el supuesto más frágil del modelo: es un pronóstico, no un dato verificable.
A16: Todo lo demás (márgenes, costos, alícuotas) está anclado en precios de mercado citados en el PDF.
... A31: npm run build — reconstruye el PDF con las mismas cifras. Los dos leen build/financiero.mjs.

Sheet Supuestos
A1: Supuestos — editar solo las celdas en amarillo
A2: Cambiá un valor amarillo y todo el libro recalcula. El resto de las hojas son fórmulas.
A4: Escenario activo | B4: Base | G4: Elegir de la lista: cambia obras y ticket de todo el modelo.
A5: Tipo de cambio (ARS por EUR) | B5: 1760 | G5: Solo afecta a la lectura en euros; la operación es en pesos.
A7: Multiplicadores de escenario
A8: Escenario | B8: Obras × | C8: Ticket × | G8: Nota
A9: Conservador | B9: 0.65 | C9: 0.9
A10: Base | B10: 1 | C10: 1
A11: Optimista | B11: 1.3 | C11: 1.05
A12: ACTIVO | B12: =INDEX(B9:B11,MATCH($B$4,$A$9:$A$11,0)) | C12: =INDEX(C9:C11,MATCH($B$4,$A$9:$A$11,0)) | G12: Lo que usa el resto del libro.
A14: Mix de producto y economía de la obra
A15: Categoría | B15: Peso en el mix | C15: Ticket (ARS) | D15: Equipo (% del ticket) | E15: Instalación (ARS) | F15: Materiales (ARS) | G15: Fuente
A16: Split premium 3.000-4.500 frig | B16: 0.45 | C16: 1800000 | D16: 0.58 | E16: 150000 | F16: 110000 | G16: F37
A17: Split 5.500-6.500 frig / multisplit 2x1 | B17: 0.35 | C17: 2800000 | D17: 0.57 | E17: 190000 | F17: 145000 | G17: F37
A18: Piso-techo, cassette o conductos | B18: 0.15 | C18: 5000000 | D18: 0.6 | E18: 450000 | F18: 300000 | G18: F37
A19: Mantenimiento y service | B19: 0.05 | C19: 250000 | D19: 0.1 | E19: 60000 | F19: 15000 | G19: F36
A20: Control: el mix tiene que sumar 100 % | B20: =SUM(B16:B19) | G20: =IF(ABS(B20-1)<0.001,"OK","REVISAR: el mix no suma 100 %")
A22: Costos variables y alícuotas
A23: Comisión de cobro (tarjeta / MP) | B23: 0.03 | G23: Sobre la facturación.
A24: Ingresos Brutos (promedio CABA + PBA) | B24: 0.024 | G24: Encuadre «instalación con provisión de equipo».
A25: Costo de adquisición de cliente (CAC) | B25: 40000 | G25: Pauta dividida por obras cerradas.
A26: Seña cobrada al firmar | B26: 0.5 | G26: Lo que financia la compra del equipo.
A27: Días hasta cobrar el saldo | B27: 15 | G27: Parte del saldo cae en el mes siguiente.
A28: Impuesto al cheque (débitos + créditos) | B28: 0.012 | G28: Computable como pago a cuenta de Ganancias (MiPyME).
A29: Ganancias — 1er tramo | B29: 0.25 | G29: Escala del art. 73 LIG.
A30: Ganancias — límite del 1er tramo | B30: 133514186 | G30: Actualizado por IPC.
A31: Ganancias — 2º tramo | B31: 0.3
A32: Ganancias — límite del 2º tramo | B32: 1335141860
A33: Ganancias — 3er tramo | B33: 0.35
A34: Costo empleador del 1er técnico | B34: 2183000 | G34: Mensual, con cargas y ART.
A35: Mes de alta del técnico (1 = primer mes) | B35: 16 | G35: Poner 99 para no contratar.
A36: Capital aportado | B36: 26400000 | G36: € 15.000
A37: Desembolsos únicos de puesta en marcha | B37: 3687200 | G37: Bloques A y B del presupuesto; salen en el mes 1.
A39: Estructura fija mensual
A40: Contador | B40: 176000
A41: Stack digital (ERP + Workspace) | B41: 167000
A42: Seguros RC + AP instaladores | B42: 273000
A43: Autónomos del gerente | B43: 141000
A44: Movilidad y combustible | B44: 211000
A45: IIBB mínimos, bancarios y varios | B45: 62000
...

Sheet Unit economics
A1: Unit economics — qué deja cada obra
A2: Todo se calcula desde «Supuestos». La obra tipo es el promedio ponderado por el mix.
A4: Categoría | B4: Mix | C4: Ticket | D4: Equipo | E4: Instalación | F4: Materiales | G4: Margen bruto | H4: % MB | I4: Comisión + IIBB | J4: Contribución
A5: =Supuestos!A16 | B5: =Supuestos!B16 | C5: =Supuestos!C16*Supuestos!$C$12 | D5: =C5*Supuestos!D16 | E5: =Supuestos!E16 | F5: =Supuestos!F16 | G5: =C5-D5-E5-F5 | H5: =IF(C5=0,0,G5/C5) | I5: =C5*(Supuestos!$B$23+Supuestos!$B$24) | J5: =G5-I5
A6: =Supuestos!A17 | B6: =Supuestos!B17 | C6: =Supuestos!C17*Supuestos!$C$12 | D6: =C6*Supuestos!D17 | E6: =Supuestos!E17 | F6: =Supuestos!F17 | G6: =C6-D6-E6-F6 | H6: =IF(C6=0,0,G6/C6) | I6: =C6*(Supuestos!$B$23+Supuestos!$B$24) | J6: =G6-I6
A7: =Supuestos!A18 | B7: =Supuestos!B18 | C7: =Supuestos!C18*Supuestos!$C$12 | D7: =C7*Supuestos!D18 | E7: =Supuestos!E18 | F7: =Supuestos!F18 | G7: =C7-D7-E7-F7 | H7: =IF(C7=0,0,G7/C7) | I7: =C7*(Supuestos!$B$23+Supuestos!$B$24) | J7: =G7-I7
A8: =Supuestos!A19 | B8: =Supuestos!B19 | C8: =Supuestos!C19*Supuestos!$C$12 | D8: =C8*Supuestos!D19 | E8: =Supuestos!E19 | F8: =Supuestos!F19 | G8: =C8-D8-E8-F8 | H8: =IF(C8=0,0,G8/C8) | I8: =C8*(Supuestos!$B$23+Supuestos!$B$24) | J8: =G8-I8
A9: OBRA TIPO (promedio ponderado) | B9: =SUM(B5:B8) | C9: =SUMPRODUCT($C$5:$C$8,$B$5:$B$8) | D9: =SUMPRODUCT($D$5:$D$8,$B$5:$B$8) | E9: =SUMPRODUCT($E$5:$E$8,$B$5:$B$8) | F9: =SUMPRODUCT($F$5:$F$8,$B$5:$B$8) | G9: =SUMPRODUCT($G$5:$G$8,$B$5:$B$8) | H9: =IF(C9=0,0,G9/C9) | I9: =SUMPRODUCT($I$5:$I$8,$B$5:$B$8) | J9: =SUMPRODUCT($J$5:$J$8,$B$5:$B$8)
A11: Menos costo de adquisición de cliente (CAC) | B11: =-Supuestos!$B$25
A12: CONTRIBUCIÓN NETA POR OBRA TIPO | B12: ='Unit economics'!$J$9-Supuestos!$B$25 | C12: =B12/Supuestos!$B$5
A13: Seña que se cobra al firmar | B13: ='Unit economics'!$C$9*Supuestos!$B$26 | G13: ← tiene que alcanzar para pagar el equipo antes de pedirlo
A14: Costo del equipo de la obra tipo | B14: ='Unit economics'!$D$9
A15: Colchón de la seña sobre el equipo | B15: =B13-B14 | G15: =IF(B15>=0,"OK: la seña cubre el equipo","ALERTA: el equipo se financia con capital propio")

Sheet P&L 24 meses
A1: Estado de resultados — 24 meses
A2: Fórmulas sobre «Supuestos» y «Unit economics». El año 1 son los meses 1-12; el año 2, los 13-24.
A4: Concepto | B4: sep-26 | C4: oct-26 | D4: nov-26 | E4: dic-26 | F4: ene-27 | G4: feb-27 | H4: mar-27 | I4: abr-27 | J4: may-27 | K4: jun-27 | L4: jul-27 | M4: ago-27 | N4: sep-27 | O4: oct-27 | P4: nov-27 | Q4: dic-27 | R4: ene-28 | S4: feb-28 | T4: mar-28 | U4: abr-28 | V4: may-28 | W4: jun-28 | X4: jul-28 | Y4: ago-28 | Z4: Año 1 | AA4: Año 2
A5: Obras | B5: =Supuestos!B$50*Supuestos!$B$12 | C5: =Supuestos!C$50*Supuestos!$B$12 | D5: =Supuestos!D$50*Supuestos!$B$12 | E5: =Supuestos!E$50*Supuestos!$B$12 | F5: =Supuestos!F$50*Supuestos!$B$12 | G5: =Supuestos!G$50*Supuestos!$B$12 | H5: =Supuestos!H$50*Supuestos!$B$12 | I5: =Supuestos!I$50*Supuestos!$B$12 | ... Y5: =Supuestos!Y$50*Supuestos!$B$12 | Z5: =SUM(B5:M5) | AA5: =SUM(N5:Y5)
A6: Facturación | B6: =B5*'Unit economics'!$C$9 | C6: =C5*'Unit economics'!$C$9 | D6: =D5*'Unit economics'!$C$9 | E6: =E5*'Unit economics'!$C$9 | F6: =F5*'Unit economics'!$C$9 | G6: =G5*'Unit economics'!$C$9 | H6: =H5*'Unit economics'!$C$9 | I6: =I5*'Unit economics'!$C$9 | ... Y6: =Y5*'Unit economics'!$C$9 | Z6: =SUM(B6:M6) | AA6: =SUM(N6:Y6)
A7: Costo de equipos | B7: =-B5*'Unit economics'!$D$9 | C7: =-C5*'Unit economics'!$D$9 | D7: =-D5*'Unit economics'!$D$9 | E7: =-E5*'Unit economics'!$D$9 | F7: =-F5*'Unit economics'!$D$9 | G7: =-G5*'Unit economics'!$D$9 | H7: =-H5*'Unit economics'!$D$9 | I7: =-I5*'Unit economics'!$D$9 | ... Y7: =-Y5*'Unit economics'!$D$9 | Z7: =SUM(B7:M7) | AA7: =SUM(N7:Y7)
A8: Instalación subcontratada | B8: =-B5*'Unit economics'!$E$9 | C8: =-C5*'Unit economics'!$E$9 | D8: =-D5*'Unit economics'!$E$9 | E8: =-E5*'Unit economics'!$E$9 | F8: =-F5*'Unit economics'!$E$9 | G8: =-G5*'Unit economics'!$E$9 | H8: =-H5*'Unit economics'!$E$9 | I8: =-I5*'Unit economics'!$E$9 | ... Y8: =-Y5*'Unit economics'!$E$9 | Z8: =SUM(B8:M8) | AA8: =SUM(N8:Y8)
A9: Materiales | B9: =-B5*'Unit economics'!$F$9 | C9: =-C5*'Unit economics'!$F$9 | D9: =-D5*'Unit economics'!$F$9 | E9: =-E5*'Unit economics'!$F$9 | F9: =-F5*'Unit economics'!$F$9 | G9: =-G5*'Unit economics'!$F$9 | H9: =-H5*'Unit economics'!$F$9 | I9: =-I5*'Unit economics'!$F$9 | ... Y9: =-Y5*'Unit economics'!$F$9 | Z9: =SUM(B9:M9) | AA9: =SUM(N9:Y9)
A10: MARGEN BRUTO | B10: =SUM(B6:B9) | C10: =SUM(C6:C9) | D10: =SUM(D6:D9) | E10: =SUM(E6:E9) | F10: =SUM(F6:F9) | G10: =SUM(G6:G9) | H10: =SUM(H6:H9) | I10: =SUM(I6:I9) | ... Y10: =SUM(Y6:Y9) | Z10: =SUM(B10:M10) | AA10: =SUM(N10:Y10)
A11: % margen bruto | B11: =IF(B6=0,0,B10/B6) | C11: =IF(C6=0,0,C10/C6) | D11: =IF(D6=0,0,D10/D6) | E11: =IF(E6=0,0,E10/E6) | F11: =IF(F6=0,0,F10/F6) | G11: =IF(G6=0,0,G10/G6) | H11: =IF(H6=0,0,H10/H6) | I11: =IF(I6=0,0,I10/I6) | ... AA11: =IF(AA6=0,0,AA10/AA6)
A12: Comisiones de cobro | B12: =-B6*Supuestos!$B$23 | C12: =-C6*Supuestos!$B$23 | D12: =-D6*Supuestos!$B$23 | E12: =-E6*Supuestos!$B$23 | F12: =-F6*Supuestos!$B$23 | G12: =-G6*Supuestos!$B$23 | H12: =-H6*Supuestos!$B$23 | I12: =-I6*Supuestos!$B$23 | ... Y12: =-Y6*Supuestos!$B$23 | Z12: =SUM(B12:M12) | AA12: =SUM(N12:Y12)
A13: Ingresos Brutos | B13: =-B6*Supuestos!$B$24 | C13: =-C6*Supuestos!$B$24 | D13: =-D6*Supuestos!$B$24 | E13: =-E6*Supuestos!$B$24 | F13: =-F6*Supuestos!$B$24 | G13: =-G6*Supuestos!$B$24 | H13: =-H6*Supuestos!$B$24 | I13: =-I6*Supuestos!$B$24 | ... Y13: =-Y6*Supuestos!$B$24 | Z13: =SUM(B13:M13) | AA13: =SUM(N13:Y13)
A14: Estructura fija | B14: =-Supuestos!$B$46 | C14: =-Supuestos!$B$46 | D14: =-Supuestos!$B$46 | E14: =-Supuestos!$B$46 | F14: =-Supuestos!$B$46 | G14: =-Supuestos!$B$46 | H14: =-Supuestos!$B$46 | I14: =-Supuestos!$B$46 | ... Y14: =-Supuestos!$B$46 | Z14: =SUM(B14:M14) | AA14: =SUM(N14:Y14)
A15: Marketing | B15: =-Supuestos!B$51 | C15: =-Supuestos!C$51 | D15: =-Supuestos!D$51 | E15: =-Supuestos!E$51 | F15: =-Supuestos!F$51 | G15: =-Supuestos!G$51 | H15: =-Supuestos!H$51 | I15: =-Supuestos!I$51 | ... Y15: =-Supuestos!Y$51 | Z15: =SUM(B15:M15) | AA15: =SUM(N15:Y15)
A16: Técnico en dependencia | B16: =IF(1>=Supuestos!$B$35,-Supuestos!$B$34,0) | C16: =IF(2>=Supuestos!$B$35,-Supuestos!$B$34,0) | D16: =IF(3>=Supuestos!$B$35,-Supuestos!$B$34,0) | E16: =IF(4>=Supuestos!$B$35,-Supuestos!$B$34,0) | F16: =IF(5>=Supuestos!$B$35,-Supuestos!$B$34,0) | G16: =IF(6>=Supuestos!$B$35,-Supuestos!$B$34,0) | H16: =IF(7>=Supuestos!$B$35,-Supuestos!$B$34,0) | I16: =IF(8>=Supuestos!$B$35,-Supuestos!$B$34,0) | J16: =IF(9>=Supuestos!$B$35,-Supuestos!$B$34,0) | K16: =IF(10>=Supuestos!$B$35,-Supuestos!$B$34,0) | L16: =IF(11>=Supuestos!$B$35,-Supuestos!$B$34,0) | M16: =IF(12>=Supuestos!$B$35,-Supuestos!$B$34,0) | N16: =IF(13>=Supuestos!$B$35,-Supuestos!$B$34,0) | O16: =IF(14>=Supuestos!$B$35,-Supuestos!$B$34,0) | P16: =IF(15>=Supuestos!$B$35,-Supuestos!$B$34,0) | Q16: =IF(16>=Supuestos!$B$35,-Supuestos!$B$34,0) | R16: =IF(17>=Supuestos!$B$35,-Supuestos!$B$34,0) | S16: =IF(18>=Supuestos!$B$35,-Supuestos!$B$34,0) | T16: =IF(19>=Supuestos!$B$35,-Supuestos!$B$34,0) | U16: =IF(20>=Supuestos!$B$35,-Supuestos!$B$34,0) | V16: =IF(21>=Supuestos!$B$35,-Supuestos!$B$34,0) | W16: =IF(22>=Supuestos!$B$35,-Supuestos!$B$34,0) | X16: =IF(23>=Supuestos!$B$35,-Supuestos!$B$34,0) | Y16: =IF(24>=Supuestos!$B$35,-Supuestos!$B$34,0) | Z16: =SUM(B16:M16) | AA16: =SUM(N16:Y16)
A17: RESULTADO OPERATIVO | B17: =B10+SUM(B12:B16) | C17: =C10+SUM(C12:C16) | D17: =D10+SUM(D12:D16) | E17: =E10+SUM(E12:E16) | F17: =F10+SUM(F12:F16) | G17: =G10+SUM(G12:G16) | H17: =H10+SUM(H12:H16) | I17: =I10+SUM(I12:I16) | ... Y17: =Y10+SUM(Y12:Y16) | Z17: =SUM(B17:M17) | AA17: =SUM(N17:Y17)
A19: Impuesto a las ganancias | B19: devengado al cierre de cada año | Z19: =-IF(Z17<=0,0,IF(Z17<=Supuestos!$B$30,Z17*Supuestos!$B$29,IF(Z17<=Supuestos!$B$32,Supuestos!$B$30*Supuestos!$B$29+(Z17-Supuestos!$B$30)*Supuestos!$B$31,Supuestos!$B$30*Supuestos!$B$29+(Supuestos!$B$32-Supuestos!$B$30)*Supuestos!$B$31+(Z17-Supuestos!$B$32)*Supuestos!$B$33))) | AA19: =-IF(AA17<=0,0,IF(AA17<=Supuestos!$B$30,AA17*Supuestos!$B$29,IF(AA17<=Supuestos!$B$32,Supuestos!$B$30*Supuestos!$B$29+(AA17-Supuestos!$B$30)*Supuestos!$B$31,Supuestos!$B$30*Supuestos!$B$29+(Supuestos!$B$32-Supuestos!$B$30)*Supuestos!$B$31+(AA17-Supuestos!$B$32)*Supuestos!$B$33)))
A20: RESULTADO NETO | Z20: =Z17+Z19 | AA20: =AA17+AA19
A21: Resultado neto en euros | Z21: =Z20/Supuestos!$B$5 | AA21: =AA20/Supuestos!$B$5

Sheet Flujo de caja
A1: Flujo de caja mensual
A2: El cliente paga seña al firmar y saldo al terminar; el mayorista cobra contado. Ese descalce es lo que consume el capital de trabajo.
A4: Concepto | B4: sep-26 | C4: oct-26 | D4: nov-26 | E4: dic-26 | F4: ene-27 | G4: feb-27 | H4: mar-27 | I4: abr-27 | J4: may-27 | K4: jun-27 | L4: jul-27 | M4: ago-27 | N4: sep-27 | O4: oct-27 | P4: nov-27 | Q4: dic-27 | R4: ene-28 | S4: feb-28 | T4: mar-28 | U4: abr-28 | V4: may-28 | W4: jun-28 | X4: jul-28 | Y4: ago-28
A5: Saldo inicial | B5: =Supuestos!$B$36 | C5: =B16 | D5: =C16 | E5: =D16 | F5: =E16 | G5: =F16 | H5: =G16 | I5: =H16 | J5: =I16 | ... Y5: =X16
A6: Cobro de señas del mes | B6: ='P&L 24 meses'!B6*Supuestos!$B$26 | C6: ='P&L 24 meses'!C6*Supuestos!$B$26 | D6: ='P&L 24 meses'!D6*Supuestos!$B$26 | E6: ='P&L 24 meses'!E6*Supuestos!$B$26 | F6: ='P&L 24 meses'!F6*Supuestos!$B$26 | G6: ='P&L 24 meses'!G6*Supuestos!$B$26 | H6: ='P&L 24 meses'!H6*Supuestos!$B$26 | I6: ='P&L 24 meses'!I6*Supuestos!$B$26 | ... Y6: ='P&L 24 meses'!Y6*Supuestos!$B$26
A7: Cobro de saldos del mes | B7: ='P&L 24 meses'!B6*(1-Supuestos!$B$26)*(1-Supuestos!$B$27/30) | C7: ='P&L 24 meses'!C6*(1-Supuestos!$B$26)*(1-Supuestos!$B$27/30) | D7: ='P&L 24 meses'!D6*(1-Supuestos!$B$26)*(1-Supuestos!$B$27/30) | E7: ='P&L 24 meses'!E6*(1-Supuestos!$B$26)*(1-Supuestos!$B$27/30) | F7: ='P&L 24 meses'!F6*(1-Supuestos!$B$26)*(1-Supuestos!$B$27/30) | G7: ='P&L 24 meses'!G6*(1-Supuestos!$B$26)*(1-Supuestos!$B$27/30) | H7: ='P&L 24 meses'!H6*(1-Supuestos!$B$26)*(1-Supuestos!$B$27/30) | I7: ='P&L 24 meses'!I6*(1-Supuestos!$B$26)*(1-Supuestos!$B$27/30) | ... Y7: ='P&L 24 meses'!Y6*(1-Supuestos!$B$26)*(1-Supuestos!$B$27/30)
A8: Cobro de saldos del mes anterior | B8: 0 | C8: ='P&L 24 meses'!B6*(1-Supuestos!$B$26)*(Supuestos!$B$27/30) | D8: ='P&L 24 meses'!C6*(1-Supuestos!$B$26)*(Supuestos!$B$27/30) | E8: ='P&L 24 meses'!D6*(1-Supuestos!$B$26)*(Supuestos!$B$27/30) | F8: ='P&L 24 meses'!E6*(1-Supuestos!$B$26)*(Supuestos!$B$27/30) | G8: ='P&L 24 meses'!F6*(1-Supuestos!$B$26)*(Supuestos!$B$27/30) | H8: ='P&L 24 meses'!G6*(1-Supuestos!$B$26)*(Supuestos!$B$27/30) | I8: ='P&L 24 meses'!H6*(1-Supuestos!$B$26)*(Supuestos!$B$27/30) | J8: ='P&L 24 meses'!I6*(1-Supuestos!$B$26)*(Supuestos!$B$27/30) | ... Y8: ='P&L 24 meses'!X6*(1-Supuestos!$B$26)*(Supuestos!$B$27/30)
A9: TOTAL COBROS | B9: =SUM(B6:B8) | C9: =SUM(C6:C8) | D9: =SUM(D6:D8) | E9: =SUM(E6:E8) | F9: =SUM(F6:F8) | G9: =SUM(G6:G8) | H9: =SUM(H6:H8) | I9: =SUM(I6:I8) | ... Y9: =SUM(Y6:Y8)
A10: Pagos operativos | B10: =-('P&L 24 meses'!B7+'P&L 24 meses'!B8+'P&L 24 meses'!B9+'P&L 24 meses'!B12+'P&L 24 meses'!B13+'P&L 24 meses'!B14+'P&L 24 meses'!B15+'P&L 24 meses'!B16) | C10: =-('P&L 24 meses'!C7+'P&L 24 meses'!C8+'P&L 24 meses'!C9+'P&L 24 meses'!C12+'P&L 24 meses'!C13+'P&L 24 meses'!C14+'P&L 24 meses'!C15+'P&L 24 meses'!C16) | D10: =-('P&L 24 meses'!D7+'P&L 24 meses'!D8+'P&L 24 meses'!D9+'P&L 24 meses'!D12+'P&L 24 meses'!D13+'P&L 24 meses'!D14+'P&L 24 meses'!D15+'P&L 24 meses'!D16) | E10: =-('P&L 24 meses'!E7+'P&L 24 meses'!E8+'P&L 24 meses'!E9+'P&L 24 meses'!E12+'P&L 24 meses'!E13+'P&L 24 meses'!E14+'P&L 24 meses'!E15+'P&L 24 meses'!E16) | F10: =-('P&L 24 meses'!F7+'P&L 24 meses'!F8+'P&L 24 meses'!F9+'P&L 24 meses'!F12+'P&L 24 meses'!F13+'P&L 24 meses'!F14+'P&L 24 meses'!F15+'P&L 24 meses'!F16) | G10: =-('P&L 24 meses'!G7+'P&L 24 meses'!G8+'P&L 24 meses'!G9+'P&L 24 meses'!G12+'P&L 24 meses'!G13+'P&L 24 meses'!G14+'P&L 24 meses'!G15+'P&L 24 meses'!G16) | H10: =-('P&L 24 meses'!H7+'P&L 24 meses'!H8+'P&L 24 meses'!H9+'P&L 24 meses'!H12+'P&L 24 meses'!H13+'P&L 24 meses'!H14+'P&L 24 meses'!H15+'P&L 24 meses'!H16) | I10: =-('P&L 24 meses'!I7+'P&L 24 meses'!I8+'P&L 24 meses'!I9+'P&L 24 meses'!I12+'P&L 24 meses'!I13+'P&L 24 meses'!I14+'P&L 24 meses'!I15+'P&L 24 meses'!I16) | ... Y10: =-('P&L 24 meses'!Y7+'P&L 24 meses'!Y8+'P&L 24 meses'!Y9+'P&L 24 meses'!Y12+'P&L 24 meses'!Y13+'P&L 24 meses'!Y14+'P&L 24 meses'!Y15+'P&L 24 meses'!Y16)
A11: Puesta en marcha (bloques A y B) | B11: =Supuestos!$B$37 | C11: 0 | D11: 0 | E11: 0 | F11: 0 | G11: 0 | H11: 0 | I11: 0 | J11: 0 | K11: 0 | L11: 0 | M11: 0 | N11: 0 | O11: 0 | P11: 0 | Q11: 0 | R11: 0 | S11: 0 | T11: 0 | U11: 0 | V11: 0 | W11: 0 | X11: 0 | Y11: 0
A12: TOTAL PAGOS | B12: =B10+B11 | C12: =C10+C11 | D12: =D10+D11 | E12: =E10+E11 | F12: =F10+F11 | G12: =G10+G11 | H12: =H10+H11 | I12: =I10+I11 | ... Y12: =Y10+Y11
A13: Impuesto al cheque | B13: =(B9+B12)*Supuestos!$B$28*0.5 | C13: =(C9+C12)*Supuestos!$B$28*0.5 | D13: =(D9+D12)*Supuestos!$B$28*0.5 | E13: =(E9+E12)*Supuestos!$B$28*0.5 | F13: =(F9+F12)*Supuestos!$B$28*0.5 | G13: =(G9+G12)*Supuestos!$B$28*0.5 | H13: =(H9+H12)*Supuestos!$B$28*0.5 | I13: =(I9+I12)*Supuestos!$B$28*0.5 | ... Y13: =(Y9+Y12)*Supuestos!$B$28*0.5
A14: Pago de Ganancias (neto de pago a cuenta) | B14: 0 | C14: 0 | D14: 0 | E14: 0 | F14: 0 | G14: 0 | H14: 0 | I14: 0 | J14: 0 | K14: 0 | L14: 0 | M14: 0 | N14: =MAX(0,-'P&L 24 meses'!Z19-SUM(B13:M13)) | O14: 0 | P14: 0 | Q14: 0 | R14: 0 | S14: 0 | T14: 0 | U14: 0 | V14: 0 | W14: 0 | X14: 0 | Y14: =MAX(0,-'P&L 24 meses'!AA19-SUM(N13:Y13))
A15: FLUJO NETO DEL MES | B15: =B9-B12-B13-B14 | C15: =C9-C12-C13-C14 | D15: =D9-D12-D13-D14 | E15: =E9-E12-E13-E14 | F15: =F9-F12-F13-F14 | G15: =G9-G12-G13-G14 | H15: =H9-H12-H13-H14 | I15: =I9-I12-I13-I14 | ... Y15: =Y9-Y12-Y13-Y14
A16: SALDO FINAL | B16: =B5+B15 | C16: =C5+C15 | D16: =D5+D15 | E16: =E5+E15 | F16: =F5+F15 | G16: =G5+G15 | H16: =H5+H15 | I16: =I5+I15 | ... Y16: =Y5+Y15
A18: Caja mínima del período | B18: =MIN(B16:Y16) | C18: =INDEX(B4:Y4,MATCH(B18,B16:Y16,0)) | D18: =IF(B18<0,"ALERTA: el capital no alcanza","OK: la caja nunca se agota")
A19: Caja al mes 24 | B19: =Y16
A20: Recupero del aporte (primer mes con caja ≥ capital) | B20: =IFERROR(INDEX(B4:Y4,MATCH(TRUE,INDEX(B16:Y16>=Supuestos!$B$36,0),0)),"no en 24 meses")

Sheet Break-even
A1: Punto de equilibrio — cuántas obras hay que hacer
A2: Obras/mes necesarias para cubrir cada nivel de estructura, con la contribución de la obra tipo.
A4: Escenario de estructura | B4: Costo a cubrir / mes | C4: Contribución por obra | D4: Obras/mes | E4: Lectura
A5: Solo estructura fija | B5: =Supuestos!$B$46 | C5: ='Unit economics'!$J$9 | D5: =IF(C5<=0,"—",B5/C5) | E5: Contador, stack, seguros, autónomos, movilidad y bancarios.
A6: Estructura + marketing de valle | B6: =Supuestos!$B$46+MIN(Supuestos!B51:M51) | C6: ='Unit economics'!$B$12 | D6: =IF(C6<=0,"—",B6/C6) | E6: Meses de invierno, con la pauta al mínimo.
A7: Estructura + marketing de temporada | B7: =Supuestos!$B$46+MAX(Supuestos!B51:M51) | C7: ='Unit economics'!$B$12 | D7: =IF(C7<=0,"—",B7/C7) | E7: Pico de diciembre-enero, con la pauta al máximo.
A8: … + primer técnico en dependencia | B8: =Supuestos!$B$46+MAX(Supuestos!B51:M51)+Supuestos!$B$34 | C8: ='Unit economics'!$B$12 | D8: =IF(C8<=0,"—",B8/C8) | E8: Costo empleador completo (Rama 17 UOM + cargas + ART).
A10: Facturación de equilibrio / mes (solo estructura) | B10: =IF('Unit economics'!$J$9=0,0,Supuestos!$B$46/('Unit economics'!$J$9/'Unit economics'!$C$9))
A11: Obras mínimas del mes valle proyectado | B11: =MIN(Supuestos!B50:M50)*Supuestos!$B$12 | E11: =IF(B11>='Break-even'!$D$8,"El valle sostiene un técnico en planta","El valle NO sostiene un técnico en planta: subcontratar")

Sheet Escenarios
A1: Escenarios — comparativa
A2: Los tres escenarios se calculan cambiando Supuestos!B4. Esta hoja guarda el resultado del escenario activo en la columna correspondiente; para completarla, seleccioná cada escenario y copiá los valores.
A4: Métrica | B4: Escenario activo | C4: Referencia del motor (base) | D4: Diferencia
A5: Obras año 1 | B5: ='P&L 24 meses'!Z5 | C5: 161 | D5: =IF(C5=0,0,(B5-C5)/C5)
A6: Facturación año 1 | B6: ='P&L 24 meses'!Z6 | C6: 410952500 | D6: =IF(C6=0,0,(B6-C6)/C6)
A7: Margen bruto año 1 | B7: ='P&L 24 meses'!Z10 | C7: 116298350 | D7: =IF(C7=0,0,(B7-C7)/C7)
A8: Resultado operativo año 1 | B8: ='P&L 24 meses'!Z17 | C8: 77046915 | D8: =IF(C8=0,0,(B8-C8)/C8)
A9: Resultado neto año 1 | B9: ='P&L 24 meses'!Z20 | C9: 57785186 | D9: =IF(C9=0,0,(B9-C9)/C9)
A10: Resultado neto año 2 | B10: ='P&L 24 meses'!AA20 | C10: 76782450 | D10: =IF(C10=0,0,(B10-C10)/C10)
A11: Caja mínima | B11: ='Flujo de caja'!$B$18 | C11: 21018476 | D11: =IF(C11=0,0,(B11-C11)/C11)
A12: Caja al mes 24 | B12: ='Flujo de caja'!$B$19 | C12: 1.5089919e+08 | D12: =IF(C12=0,0,(B12-C12)/C12)
A14: Escenario activo | B14: =Supuestos!B4 | D14: =IF(Supuestos!B4="Base",IF(SUMPRODUCT(MAX(ABS(D5:D12)))<0.005,"OK: coincide con el motor del PDF","REVISAR: diverge del motor"),"Cambiá a «Base» para contrastar contra el motor")

Sheet Dashboard
A1: Dashboard — las cifras que miran los socios
A2: Todo se mueve con el escenario elegido en Supuestos!B4 y con las series mensuales.
A4: Escenario activo | B4: =Supuestos!B4 | D4: Cambiar en la hoja «Supuestos».
A5: Obras del año 1 | B5: ='P&L 24 meses'!Z5 | D5: Suma de los primeros 12 meses.
A6: Facturación del año 1 | B6: ='P&L 24 meses'!Z6
A7: Margen bruto del año 1 | B7: ='P&L 24 meses'!Z11 | D7: Después de equipo, instalación y materiales.
A8: Resultado neto del año 1 | B8: ='P&L 24 meses'!Z20
A9: Resultado neto del año 1 (EUR) | B9: ='P&L 24 meses'!Z21 | D9: Al TC de la hoja «Supuestos».
A10: Resultado neto del año 2 (EUR) | B10: ='P&L 24 meses'!AA21
A11: Caja mínima del período | B11: ='Flujo de caja'!$B$18 | D11: Si es negativa, el capital no alcanza.
A12: Caja al mes 24 | B12: ='Flujo de caja'!$B$19
A13: Recupero del aporte | B13: ='Flujo de caja'!$B$20 | D13: Primer mes con caja ≥ capital aportado.
A14: Contribución por obra tipo | B14: ='Unit economics'!$J$9 | D14: Antes del CAC.
A15: Break-even en temporada | B15: ='Break-even'!$D$7 | D15: Obras/mes con la pauta al máximo.
A16: Break-even con técnico en planta | B16: ='Break-even'!$D$8 | D16: La razón para subcontratar.
A18: Curva de caja y resultado operativo
A19: Mes | B19: Saldo de caja | C19: Resultado operativo
A20: ='Flujo de caja'!B4 | B20: ='Flujo de caja'!B16 | C20: ='P&L 24 meses'!B17
A21: ='Flujo de caja'!C4 | B21: ='Flujo de caja'!C16 | C21: ='P&L 24 meses'!C17
A22: ='Flujo de caja'!D4 | B22: ='Flujo de caja'!D16 | C22: ='P&L 24 meses'!D17
A23: ='Flujo de caja'!E4 | B23: ='Flujo de caja'!E16 | C23: ='P&L 24 meses'!E17
A24: ='Flujo de caja'!F4 | B24: ='Flujo de caja'!F16 | C24: ='P&L 24 meses'!F17
A25: ='Flujo de caja'!G4 | B25: ='Flujo de caja'!G16 | C25: ='P&L 24 meses'!G17
A26: ='Flujo de caja'!H4 | B26: ='Flujo de caja'!H16 | C26: ='P&L 24 meses'!H17
A27: ='Flujo de caja'!I4 | B27: ='Flujo de caja'!I16 | C27: ='P&L 24 meses'!I17
A28: ='Flujo de caja'!J4 | B28: ='Flujo de caja'!J16 | C28: ='P&L 24 meses'!J17
A29: ='Flujo de caja'!K4 | B29: ='Flujo de caja'!K16 | C29: ='P&L 24 meses'!K17
A30: ='Flujo de caja'!L4 | B30: ='Flujo de caja'!L16 | C30: ='P&L 24 meses'!L17
A31: ='Flujo de caja'!M4 | B31: ='Flujo de caja'!M16 | C31: ='P&L 24 meses'!M17
A32: ='Flujo de caja'!N4 | B32: ='Flujo de caja'!N16 | C32: ='P&L 24 meses'!N17
A33: ='Flujo de caja'!O4 | B33: ='Flujo de caja'!O16 | C33: ='P&L 24 meses'!O17
A34: ='Flujo de caja'!P4 | B34: ='Flujo de caja'!P16 | C34: ='P&L 24 meses'!P17
A35: ='Flujo de caja'!Q4 | B35: ='Flujo de caja'!Q16 | C35: ='P&L 24 meses'!Q17
A36: ='Flujo de caja'!R4 | B36: ='Flujo de caja'!R16 | C36: ='P&L 24 meses'!R17
A37: ='Flujo de caja'!S4 | B37: ='Flujo de caja'!S16 | C37: ='P&L 24 meses'!S17
A38: ='Flujo de caja'!T4 | B38: ='Flujo de caja'!T16 | C38: ='P&L 24 meses'!T17
A39: ='Flujo de caja'!U4 | B39: ='Flujo de caja'!U16 | C39: ='P&L 24 meses'!U17
A40: ='Flujo de caja'!V4 | B40: ='Flujo de caja'!V16 | C40: ='P&L 24 meses'!V17
A41: ='Flujo de caja'!W4 | B41: ='Flujo de caja'!W16 | C41: ='P&L 24 meses'!W17
A42: ='Flujo de caja'!X4 | B42: ='Flujo de caja'!X16 | C42: ='P&L 24 meses'!X17
...

Sheet Verificación
A1: Verificación — Excel contra el motor del PDF
A2: Con los supuestos originales y el escenario en «Base», estas dos columnas coinciden al centavo: es la prueba de que la planilla y el PDF cuentan lo mismo. En cuanto se edita un supuesto la planilla se separa del PDF a propósito — ahí «HAY DIVERGENCIAS» significa «estás modelando algo distinto de lo publicado», no que haya un error.
A4: Cifra de control | B4: Planilla | C4: Motor del PDF | D4: Desvío | E4: Estado
A5: Obras año 1 | B5: ='P&L 24 meses'!Z5 | C5: 161 | D5: =IF(C5=0,0,(B5-C5)/C5) | E5: =IF(ABS(D5)<0.005,"OK","REVISAR")
A6: Facturación año 1 | B6: ='P&L 24 meses'!Z6 | C6: 410952500 | D6: =IF(C6=0,0,(B6-C6)/C6) | E6: =IF(ABS(D6)<0.005,"OK","REVISAR")
A7: Margen bruto año 1 | B7: ='P&L 24 meses'!Z10 | C7: 116298350 | D7: =IF(C7=0,0,(B7-C7)/C7) | E7: =IF(ABS(D7)<0.005,"OK","REVISAR")
A8: Resultado operativo año 1 | B8: ='P&L 24 meses'!Z17 | C8: 77046915 | D8: =IF(C8=0,0,(B8-C8)/C8) | E8: =IF(ABS(D8)<0.005,"OK","REVISAR")
A9: Resultado neto año 1 | B9: ='P&L 24 meses'!Z20 | C9: 57785186 | D9: =IF(C9=0,0,(B9-C9)/C9) | E9: =IF(ABS(D9)<0.005,"OK","REVISAR")
A10: Resultado neto año 2 | B10: ='P&L 24 meses'!AA20 | C10: 76782450 | D10: =IF(C10=0,0,(B10-C10)/C10) | E10: =IF(ABS(D10)<0.005,"OK","REVISAR")
A11: Caja mínima | B11: ='Flujo de caja'!$B$18 | C11: 21018476 | D11: =IF(C11=0,0,(B11-C11)/C11) | E11: =IF(ABS(D11)<0.005,"OK","REVISAR")
A12: Caja al mes 24 | B12: ='Flujo de caja'!$B$19 | C12: 1.5089919e+08 | D12: =IF(C12=0,0,(B12-C12)/C12) | E12: =IF(ABS(D12)<0.005,"OK","REVISAR")
A13: Contribución por obra tipo | B13: ='Unit economics'!$J$9 | C13: 584515 | D13: =IF(C13=0,0,(B13-C13)/C13) | E13: =IF(ABS(D13)<0.005,"OK","REVISAR")
A14: Break-even en temporada (obras/mes) | B14: ='Break-even'!$D$7 | C14: 3.1771393 | D14: =IF(C14=0,0,(B14-C14)/C14) | E14: =IF(ABS(D14)<0.005,"OK","REVISAR")
A16: RESULTADO GLOBAL | B16: =IF(COUNTIF(E5:E14,"REVISAR")=0,"OK — planilla y PDF cuentan lo mismo","La planilla ya no refleja el PDF (esperable si editaste supuestos)")
